Traceback (most recent call last):
  File "C:\Users\simio\AppData\Local\Programs\Python\Python310\lib\site-packages\torch\utils\data\dataloader.py", line 1132, in _try_get_data
    data = self._data_queue.get(timeout=timeout)
  File "C:\Users\simio\AppData\Local\Programs\Python\Python310\lib\queue.py", line 179, in get
    raise Empty
_queue.Empty
The above exception was the direct cause of the following exception:
Traceback (most recent call last):
  File "D:\Facultate\Master\Anul 1\Semestrul 2\Analiza Experimentala a Algoritmilor\EAA-Graph-Coloring\Graph Neural Network\TrainingPipeline.py", line 121, in run_config
    self.train(model, criterion, optimizer, train_loader)
  File "D:\Facultate\Master\Anul 1\Semestrul 2\Analiza Experimentala a Algoritmilor\EAA-Graph-Coloring\Graph Neural Network\TrainingPipeline.py", line 71, in train
    for data in train_loader:  # Iterate in batches over the training dataset.
  File "C:\Users\simio\AppData\Local\Programs\Python\Python310\lib\site-packages\torch\utils\data\dataloader.py", line 630, in __next__
    data = self._next_data()
  File "C:\Users\simio\AppData\Local\Programs\Python\Python310\lib\site-packages\torch\utils\data\dataloader.py", line 1328, in _next_data
    idx, data = self._get_data()
  File "C:\Users\simio\AppData\Local\Programs\Python\Python310\lib\site-packages\torch\utils\data\dataloader.py", line 1284, in _get_data
    success, data = self._try_get_data()
  File "C:\Users\simio\AppData\Local\Programs\Python\Python310\lib\site-packages\torch\utils\data\dataloader.py", line 1145, in _try_get_data
    raise RuntimeError(f'DataLoader worker (pid(s) {pids_str}) exited unexpectedly') from e
RuntimeError: DataLoader worker (pid(s) 17888, 22600) exited unexpectedly